Workbook

Sheet Propane Boiler BAU ReOPT
A1: Scenario | B1: Full cost (25 year) | C1: NPV savings (10 year) | D1: REopt Results: | E1: Select Technologies to Evaluate | F1: Evaluation name | G1: Site location (latitude, longitude) | H1: PV & wind space available | I1: Roofspace available (sq ft) | J1: Electricity rate | K1: Compensation type | L1: Existing heating system fuel type | M1: Annual existing heating system fuel cost ($/gallon) | N1: Upload typical electric load profile | O1: Year of load profile | P1: Upload typical heating load profile | Q1: Space heating load percent of total heating load (%) | R1: Year of load profile | S1: Existing heating system efficiency (% HHV-basis) | T1: Analysis period (years) | U1: Host discount rate, nominal (%) | V1: Electricity cost escalation rate, nominal (%/year) | W1: Existing heating system fuel cost escalation rate, nominal (%/year) | X1: Host effective tax rate (%) | Y1: Emissions | Z1: Size class | AA1: System capital cost ($/kW-DC) | AB1: Array type | AC1: Array azimuth (deg) | AD1: Array tilt (deg) | AE1: Federal Incentive based on percentage of cost (%) | AF1: MACRS schedule | AG1: MACRS bonus depreciation | AH1: REopt Results: | AI1: Optimized PV size (kW) | AJ1: Optimized ASHP size (tonnes) | AK1: Potential Life Cycle Savings | AL1: Avg. Annual Grid Serving Load (kWh) | AM1: Avg. Annual Grid Charging Battery (kWh) | AN1: Avg. Annual Grid Total Electricity Consumed (kWh) | AO1: Avg. Annual PV Serving Load (kWh) | AP1: Avg. Annual PV Charging Battery (kWh) | AQ1: Avg. Annual PV Exported to Grid (kWh) | AR1: Avg. Annual PV Curtailment (kWh) | AS1: Avg. Annual PV Total Electricity Produced (kWh) | AT1: Avg. Annual Battery Serving Load (kWh) | AU1: BAU Average Annual Energy Supplied from Grid (kWh) | AV1: System Average Annual Energy Supplied from Grid (kWh) | AW1: Difference in Avg. Annual Energy Supplied from Grid | AX1: w/PV Annual Renewable Electricity (% of electricity consumed) | AY1: PV Avoided CO2e Emissions throughout Analysis Period | AZ1: BAU Total Year 1 Elec Cost - Pre-Tax | BA1: Total Year 1 Elec Cost - Pre-Tax | BB1: Difference Total Year 1 Elec Cost | BC1: BAU Total Full Period Elec Cost | BD1: Optimized Total Full Period Elec Cost | BE1: Difference in Full Period Utility Cost | BF1: BAUTotal Life Cycle Costs | BG1: Total Life Cycle Costs | BI1: Net Present Value | BJ1: Payback Period for PV /Battery (yrs)
A2: Broken controls propane boiler, full cost | D2: Broken controls propane boiler, full cost | REopt Web Tool | REopt Energy Integration & Optimization | NLR | E2: PV (but roofspace 0) | F2: Broken controls propane boiler, full cost | G2: 47.85212, -122.56923 | H2: Roofspace only | I2: 0 | J2: PSE: 24 (General Service - Three Phase) | K2: No compensation for exports | L2: propane | M2: 2.01 | N2: https://drive.google.com/file/d/1Xl5WOtWsJzfbC-Y8nCxkp4Y4Mozirc_L/view?usp=drive_link | O2: 2024 | P2: https://drive.google.com/file/d/12MjGV739OVxdOUym7sn516wQM4dv51MR/view?usp=drive_link | Q2: 100 | R2: 2024 | S2: 83.07 | T2: 25 | U2: 2.5 | V2: 6 | W2: 7.8 | X2: 0 | Y2: - | Z2: Small Commercial | AA2: 2220 | AB2: Rooftop, Fixed | AC2: 335.4 | AD2: 10.7 | AE2: 0 | AF2: No MACRS | AG2: 0 | AH2: Broken controls propane boiler, full cost | REopt Web Tool | REopt Energy Integration & Optimization | NLR | AZ2: 355438 | BA2: 355438 | BF2: 916753 | BG2: 916753
A3: Broken controls propane boiler, free capital | D3: Broken controls propane boiler, free capital | REopt Web Tool | REopt Energy Integration & Optimization | NLR | E3: PV (but roofspace 0) | F3: Broken controls propane boiler, free capital | G3: 47.85212, -122.56923 | H3: Roofspace only | I3: 0 | J3: PSE: 24 (General Service - Three Phase) | K3: No compensation for exports | L3: propane | M3: 2.01 | N3: https://drive.google.com/file/d/1Xl5WOtWsJzfbC-Y8nCxkp4Y4Mozirc_L/view?usp=drive_link | O3: 2024 | P3: https://drive.google.com/file/d/12MjGV739OVxdOUym7sn516wQM4dv51MR/view?usp=drive_link | Q3: 100 | R3: 2024 | S3: 83.07 | T3: 10 | U3: 2.5 | V3: 6 | W3: 7.8 | X3: 0 | Y3: - | Z3: Small Commercial | AA3: 0 | AB3: Rooftop, Fixed | AC3: 335.4 | AD3: 10.7 | AE3: 0 | AF3: No MACRS | AG3: 0 | AH3: Broken controls propane boiler, free capital | REopt Web Tool | REopt Energy Integration & Optimization | NLR | AZ3: 107850 | BA3: 107850 | BF3: 316497 | BG3: 316497
A5: Fixed controls propane boiler, full cost | D5: Fixed controls propane boiler, full cost | REopt Web Tool | REopt Energy Integration & Optimization | NLR | E5: PV (but roofspace 0) | F5: Broken controls propane boiler, full cost | G5: 47.85212, -122.56923 | H5: Roofspace only | I5: 0 | J5: PSE: 24 (General Service - Three Phase) | K5: No compensation for exports | L5: propane | M5: 2.01 | N5: https://drive.google.com/file/d/1Xl5WOtWsJzfbC-Y8nCxkp4Y4Mozirc_L/view?usp=drive_link | O5: 2024 | P5: https://drive.google.com/file/d/12MjGV739OVxdOUym7sn516wQM4dv51MR/view?usp=drive_link | Q5: 100 | R5: 2024 | S5: 83.07 | T5: 25 | U5: 2.5 | V5: 6 | W5: 7.8 | X5: 0 | Y5: - | Z5: Small Commercial | AA5: 2220 | AB5: Rooftop, Fixed | AC5: 335.4 | AD5: 10.7 | AE5: 0 | AF5: No MACRS | AG5: 0 | AH5: Fixed controls propane boiler, full cost | REopt Web Tool | REopt Energy Integration & Optimization | NLR | AZ5: 355438 | BA5: 355438 | BF5: 881918 | BG5: 881918
A6: Fixed controls propane boiler, free capital | D6: Fixed controls propane boiler, free capital | REopt Web Tool | REopt Energy Integration & Optimization | NLR | E6: PV (but roofspace 0) | F6: Broken controls propane boiler, free capital | G6: 47.85212, -122.56923 | H6: Roofspace only | I6: 0 | J6: PSE: 24 (General Service - Three Phase) | K6: No compensation for exports | L6: propane | M6: 2.01 | N6: https://drive.google.com/file/d/1Xl5WOtWsJzfbC-Y8nCxkp4Y4Mozirc_L/view?usp=drive_link | O6: 2024 | P6: https://drive.google.com/file/d/12MjGV739OVxdOUym7sn516wQM4dv51MR/view?usp=drive_link | Q6: 100 | R6: 2024 | S6: 83.07 | T6: 10 | U6: 2.5 | V6: 6 | W6: 7.8 | X6: 0 | Y6: - | Z6: Small Commercial | AA6: 0 | AB6: Rooftop, Fixed | AC6: 335.4 | AD6: 10.7 | AE6: 0 | AF6: No MACRS | AG6: 0 | AH6: Fixed controls propane boiler, free capital | REopt Web Tool | REopt Energy Integration & Optimization | NLR | AZ6: 107850 | BA6: 107850 | BF6: 303549 | BG6: 303549

Sheet LT Heat Pumps
A1: Scenario | B1: Neither | C1: Net metering | D1: Net billing | E1: No PV | F1: CEC & EC PV | G1: Full cost (25 year) | H1: NPV savings (10 year) | I1: REopt Results: | J1: Select Technologies to Evaluate | K1: Air-Source Heat Pump configuration | L1: Evaluation name | M1: Site location (latitude, longitude) | N1: PV & wind space available | O1: Roofspace available (sq ft) | P1: Electricity rate | Q1: Compensation type | R1: Net metering system size limit (kW) | S1: Net billing compensation for all exports ($/kWh) | T1: Existing heating system fuel type | U1: Annual existing heating system fuel cost ($/gallon) | V1: Upload typical electric load profile | W1: Year of load profile | X1: Upload typical heating load profile | Y1: Space heating load percent of total heating load (%) | Z1: Year of load profile | AA1: Existing heating system efficiency (% HHV-basis) | AB1: Analysis period (years) | AC1: Host discount rate, nominal (%) | AD1: Electricity cost escalation rate, nominal (%/year) | AE1: Existing heating system fuel cost escalation rate, nominal (%/year) | AF1: Host effective tax rate (%) | AG1: Emissions | AH1: Size class | AI1: System capital cost ($/kW-DC) | AJ1: Array type | AK1: Array azimuth (deg) | AL1: Array tilt (deg) | AM1: Federal Incentive based on percentage of cost (%) | AN1: MACRS schedule | AO1: MACRS bonus depreciation | AP1: Energy capacity cost ($/kWh) | AQ1: Power capacity cost ($/kW) | AR1: Constant cost ($) | AS1: Minimum energy capacity (kWh) | AT1: Maximum energy capacity (kWh) | AU1: Energy capacity replacement cost ($/kWh) | AV1: Power capacity replacement cost ($/kWh) | AW1: Constant replacement cost ($) | AX1: Minimum power capacity (kW) | AY1: Maximum power capacity (kW) | AZ1: Federal Incentive based on percentage of cost (%) | BA1: MACRS schedule | BB1: MACRS bonus depreciation | BC1: Total installed cost ($/ton) | BD1: Upload COP Table | BE1: Heat pump capacity sizing factor | BF1: Resistive heating back-up temperature threshold (°F) | BG1: MACRS schedule | BH1: MACRS bonus depreciation | BI1: REopt Results: | BJ1: Optimized PV size (kW) | BK1: Optimized ASHP size (tonnes) | BL1: Optimized Battery Power and Capacity (kW/kWh) | BM1: Potential Life Cycle Savings | BN1: Avg. Annual Grid Serving Load (kWh) | BO1: Avg. Annual Grid Charging Battery (kWh) | BP1: Avg. Annual Grid Total Electricity Consumed (kWh) | BQ1: Avg. Annual PV Serving Load (kWh) | BR1: Avg. Annual PV Charging Battery (kWh) | BS1: Avg. Annual PV Exported to Grid (kWh) | BT1: Avg. Annual PV Curtailment (kWh) | BU1: Avg. Annual PV Total Electricity Produced (kWh) | BV1: Avg. Annual Battery Serving Load (kWh) | BW1: BAU Average Annual Energy Supplied from Grid (kWh) | BX1: System Average Annual Energy Supplied from Grid (kWh) | BY1: Difference in Avg. Annual Energy Supplied from Grid | BZ1: Annual Renewable Electricity (% of electricity consumed) | CA1: BAU Total Year 1 Elec Cost - Pre-Tax | CB1: Total Year 1 Elec Cost - Pre-Tax | CC1: Difference Total Year 1 Elec Cost | CD1: BAU Total Full Period Elec Cost | CE1: PV Total Full Period Elec Cost | CF1: Difference in Full Period Utility Cost | CG1: BAU Total Life Cycle Costs | CH1: PV/Battery Total Life Cycle Costs | CI1: Difference in Total life cycle costs | CJ1: w/PV/ Battery Net Present Value | CK1: Payback Period for PV /Battery (yrs)
A2: LT Heat Pumps, no PV, full cost | I2: LT Heat Pumps, no PV, full cost | J2: ASHP | K2: 2: Full replacement heating | L2: LT Heat Pumps, no PV, full cost | M2: 47.85212, -122.56923 | N2: Roofspace only | O2: 8000 | P2: PSE: 25 | Q2: N/A | R2: - | S2: - | T2: propane | U2: 2.01 | V2: https://drive.google.com/file/d/1Xl5WOtWsJzfbC-Y8nCxkp4Y4Mozirc_L/view?usp=drive_link | W2: 2024 | X2: https://drive.google.com/file/d/12MjGV739OVxdOUym7sn516wQM4dv51MR/view?usp=drive_link | Y2: 100 | Z2: 2024 | AA2: 83.07 | AB2: 25 | AC2: 2.5 | AD2: 6 | AE2: 7.8 | AF2: 0 | AG2: - | AH2: - | AI2: - | AJ2: - | AK2: - | AL2: - | AM2: - | AN2: - | AO2: - | AP2: - | AQ2: - | AR2: - | AS2: - | AT2: - | AU2: - | AV2: - | AW2: - | AX2: - | AY2: - | AZ2: - | BA2: - | BB2: - | BC2: 0 | BD2: https://drive.google.com/file/d/1jrpu40DzxTFYY6LiD8LJLWmYTYBMVds2/view?usp=drive_link | BE2: 1 | BF2: 10 | BG2: No MACRS | BH2: 0 | BI2: LT Heat Pumps, no PV, full cost | BJ2: - | BK2: 35 | BL2: - | BM2: -86028 | BN2: - | BO2: - | BP2: - | BQ2: - | BR2: - | BS2: - | BT2: - | BU2: - | BV2: - | BW2: 44197 | BX2: 132850 | BY2: =BX2-BW2 -> 88653 | BZ2: 0 | CA2: 8394 | CB2: 23773 | CC2: =CB2-CA2 -> 15379 | CD2: 334284 | CE2: 946792 | CF2: =CE2-CD2 -> 612508 | CG2: 860764 | CH2: 946792 | CI2: =CH2-CG2 -> 86028 | CJ2: -86028 | CK2: 0
A3: LT Heat Pumps, no PV, free capital | I3: LT Heat Pumps, no PV, free capital | J3: ASHP | K3: 2: Full replacement heating | L3: LT Heat Pumps, no PV, free capital | M3: 47.85212, -122.56923 | N3: Roofspace only | O3: 8000 | P3: PSE: 25 | Q3: N/A | R3: - | S3: - | T3: propane | U3: 2.01 | V3: https://drive.google.com/file/d/1Xl5WOtWsJzfbC-Y8nCxkp4Y4Mozirc_L/view?usp=drive_link | W3: 2024 | X3: https://drive.google.com/file/d/12MjGV739OVxdOUym7sn516wQM4dv51MR/view?usp=drive_link | Y3: 100 | Z3: 2024 | AA3: 83.07 | AB3: 10 | AC3: 2.5 | AD3: 6 | AE3: 7.8 | AF3: 0 | AG3: - | AH3: - | AI3: - | AJ3: - | AK3: - | AL3: - | AM3: - | AN3: - | AO3: - | AP3: - | AQ3: - | AR3: - | AS3: - | AT3: - | AU3: - | AV3: - | AW3: - | AX3: - | AY3: - | AZ3: - | BA3: - | BB3: - | BC3: 0 | BD3: https://drive.google.com/file/d/1jrpu40DzxTFYY6LiD8LJLWmYTYBMVds2/view?usp=drive_link | BE3: 1 | BF3: 10 | BG3: No MACRS | BH3: 0 | BI3: LT Heat Pumps, no PV, free capital | BJ3: - | BK3: 35 | BL3: - | BM3: 9846 | BN3: - | BO3: - | BP3: - | BQ3: - | BR3: - | BS3: - | BT3: - | BU3: - | BV3: - | BW3: 44197 | BX3: 132850 | BY3: =BX3-BW3 -> 88653 | BZ3: 0 | CA3: 8394 | CB3: 23773 | CC3: =CB3-CA3 -> 15379 | CD3: 101431 | CE3: 287284 | CF3: =CE3-CD3 -> 185853 | CG3: 297130 | CH3: 287284 | CI3: =CH3-CG3 -> -9846 | CJ3: 9846 | CK3: 0
A4: LT Heat Pumps, net metering, full cost | I4: LT Heat Pumps, net metering, full cost | J4: ASHP, PV | K4: 2: Full replacement heating | L4: LT Heat Pumps, net metering, full cost | M4: 47.85212, -122.56923 | N4: Roofspace only | O4: 8000 | P4: PSE: 25 | Q4: Net metering | R4: 100 | S4: - | T4: propane | U4: 2.01 | V4: https://drive.google.com/file/d/1Xl5WOtWsJzfbC-Y8nCxkp4Y4Mozirc_L/view?usp=drive_link | W4: 2024 | X4: https://drive.google.com/file/d/12MjGV739OVxdOUym7sn516wQM4dv51MR/view?usp=drive_link | Y4: 100 | Z4: 2024 | AA4: 83.07 | AB4: 25 | AC4: 2.5 | AD4: 6 | AE4: 7.8 | AF4: 0 | AG4: - | AH4: Small Commercial | AI4: 2220 | AJ4: Rooftop, Fixed | AK4: 335.4 | AL4: 10.7 | AM4: 0 | AN4: No MACRS | AO4: 0 | AP4: - | AQ4: - | AR4: - | AS4: - | AT4: - | AU4: - | AV4: - | AW4: - | AX4: - | AY4: - | AZ4: - | BA4: - | BB4: - | BC4: 0 | BD4: https://drive.google.com/file/d/1jrpu40DzxTFYY6LiD8LJLWmYTYBMVds2/view?usp=drive_link | BE4: 1 | BF4: 10 | BG4: No MACRS | BH4: 0 | BI4: LT Heat Pumps, net metering, full cost | BJ4: 80 | BK4: 35 | BL4: - | BM4: 74069 | BN4: 105036 | BO4: 0 | BP4: =BN4-BO4 -> 105036 | BQ4: 27815 | BR4: 0 | BS4: 34023 | BT4: 0 | BU4: =BQ4+BR4+BS4+BT4 -> 61838 | BV4: - | BW4: 44197 | BX4: =BP4 -> 105036 | BY4: =BX4-BW4 -> 60839 | BZ4: 0.47 | CA4: 8394 | CB4: 13988 | CC4: =CB4-CA4 -> 5594 | CD4: 334284 | CE4: 557095 | CF4: =CE4-CD4 -> 222811 | CG4: 860764 | CH4: 786695 | CI4: =CH4-CG4 -> -74069 | CJ4: 74069 | CK4: 13.88
A5: LT Heat Pumps, net metering, free capital | I5: LT Heat Pumps, net metering, free capital | J5: ASHP, PV | K5: 2: Full replacement heating | L5: LT Heat Pumps, net metering, free capital | M5: 47.85212, -122.56923 | N5: Roofspace only | O5: 8000 | P5: PSE: 25 | Q5: Net metering | R5: 100 | S5: - | T5: propane | U5: 2.01 | V5: https://drive.google.com/file/d/1Xl5WOtWsJzfbC-Y8nCxkp4Y4Mozirc_L/view?usp=drive_link | W5: 2024 | X5: https://drive.google.com/file/d/12MjGV739OVxdOUym7sn516wQM4dv51MR/view?usp=drive_link | Y5: 100 | Z5: 2024 | AA5: 83.07 | AB5: 10 | AC5: 2.5 | AD5: 6 | AE5: 7.8 | AF5: 0 | AG5: - | AH5: Small Commercial | AI5: 0 | AJ5: Rooftop, Fixed | AK5: 335.4 | AL5: 10.7 | AM5: 0 | AN5: No MACRS | AO5: 0 | AP5: - | AQ5: - | AR5: - | AS5: - | AT5: - | AU5: - | AV5: - | AW5: - | AX5: - | AY5: - | AZ5: - | BA5: - | BB5: - | BC5: 0 | BD5: https://drive.google.com/file/d/1jrpu40DzxTFYY6LiD8LJLWmYTYBMVds2/view?usp=drive_link | BE5: 1 | BF5: 10 | BG5: No MACRS | BH5: 0 | BI5: LT Heat Pumps, net metering, free capital | BJ5: 80 | BK5: 35 | BL5: - | BM5: 112478 | BN5: 104535 | BO5: 0 | BP5: =BN5-BO5 -> 104535 | BQ5: 28315 | BR5: 0 | BS5: 36325 | BT5: 0 | BU5: =BQ5+BR5+BS5+BT5+1 -> 64641 | BV5: - | BW5: 44197 | BX5: =BP5 -> 104535 | BY5: =BX5-BW5 -> 60338 | BZ5: 0.49 | CA5: 8394 | CB5: 13559 | CC5: =CB5-CA5 -> 5165 | CD5: 101431 | CE5: 163852 | CF5: =CE5-CD5 -> 62421 | CG5: 297130 | CH5: 184652 | CI5: =CH5-CG5 -> -112478 | CJ5: 112478 | CK5: 0
A6: LT Heat Pumps, net billing, full cost | I6: LT Heat Pumps, net billing, full cost | J6: ASHP, PV | K6: 2: Full replacement heating | L6: LT Heat Pumps, net billing, full cost | M6: 47.85212, -122.56923 | N6: Roofspace only | O6: 8000 | P6: PSE: 25 | Q6: Net billing | R6: - | S6: 0.06713 | T6: propane | U6: 2.01 | V6: https://drive.google.com/file/d/1Xl5WOtWsJzfbC-Y8nCxkp4Y4Mozirc_L/view?usp=drive_link | W6: 2024 | X6: https://drive.google.com/file/d/12MjGV739OVxdOUym7sn516wQM4dv51MR/view?usp=drive_link | Y6: 100 | Z6: 2024 | AA6: 83.07 | AB6: 25 | AC6: 2.5 | AD6: 6 | AE6: 7.8 | AF6: 0 | AG6: - | AH6: Small Commercial | AI6: 2220 | AJ6: Rooftop, Fixed | AK6: 335.4 | AL6: 10.7 | AM6: 0 | AN6: No MACRS | AO6: 0 | AP6: - | AQ6: - | AR6: - | AS6: - | AT6: - | AU6: - | AV6: - | AW6: - | AX6: - | AY6: - | AZ6: - | BA6: - | BB6: - | BC6: 0 | BD6: https://drive.google.com/file/d/1jrpu40DzxTFYY6LiD8LJLWmYTYBMVds2/view?usp=drive_link | BE6: 1 | BF6: 10 | BG6: No MACRS | BH6: 0 | BI6: LT Heat Pumps, net billing, full cost | BJ6: 55 | BK6: 35 | BL6: - | BM6: -33927 | BN6: 109169 | BO6: 0 | BP6: =BN6-BO6 -> 109169 | BQ6: 23682 | BR6: 0 | BS6: 18814 | BT6: 0 | BU6: =BQ6+BR6+BS6+BT6 -> 42496 | BV6: - | BW6: 44197 | BX6: =BP6 -> 109169 | BY6: =BX6-BW6 -> 64972 | BZ6: 0.32 | CA6: 8394 | CB6: 18503 | CC6: =CB6-CA6 -> 10109 | CD6: 334284 | CE6: 736908 | CF6: =CE6-CD6 -> 402624 | CG6: 860764 | CH6: 894691 | CI6: =CH6-CG6 -> 33927 | CJ6: -33927 | CK6: 0
A7: LT Heat Pumps, net billing, free capital | I7: LT Heat Pumps, net billing, free capital | J7: ASHP, PV | K7: 2: Full replacement heating | L7: LT Heat Pumps, net billing, free capital | M7: 47.85212, -122.56923 | N7: Roofspace only | O7: 8000 | P7: PSE: 25 | Q7: Net billing | R7: - | S7: 0.06713 | T7: propane | U7: 2.01 | V7: https://drive.google.com/file/d/1Xl5WOtWsJzfbC-Y8nCxkp4Y4Mozirc_L/view?usp=drive_link | W7: 2024 | X7: https://drive.google.com/file/d/12MjGV739OVxdOUym7sn516wQM4dv51MR/view?usp=drive_link | Y7: 100 | Z7: 2024 | AA7: 83.07 | AB7: 10 | AC7: 2.5 | AD7: 6 | AE7: 7.8 | AF7: 0 | AG7: - | AH7: Small Commercial | AI7: 0 | AJ7: Rooftop, Fixed | AK7: 335.4 | AL7: 10.7 | AM7: 0 | AN7: No MACRS | AO7: 0 | AP7: - | AQ7: - | AR7: - | AS7: - | AT7: - | AU7: - | AV7: - | AW7: - | AX7: - | AY7: - | AZ7: - | BA7: - | BB7: - | BC7: 0 | BD7: https://drive.google.com/file/d/1jrpu40DzxTFYY6LiD8LJLWmYTYBMVds2/view?usp=drive_link | BE7: 1 | BF7: 10 | BG7: No MACRS | BH7: 0 | BI7: LT Heat Pumps, net billing, free capital | BJ7: 80 | BK7: 35 | BL7: - | BM7: 76572 | BN7: 104535 | BO7: 0 | BP7: =BN7-BO7 -> 104535 | BQ7: 28315 | BR7: 0 | BS7: 36325 | BT7: 0 | BU7: =BQ7+BR7+BS7+BT7 -> 64640 | BV7: - | BW7: 44197 | BX7: =BP7 -> 104535 | BY7: =BX7-BW7 -> 60338 | BZ7: 0.49 | CA7: 8394 | CB7: 16530 | CC7: =CB7-CA7 -> 8136 | CD7: 101431 | CE7: 199758 | CF7: =CE7-CD7 -> 98327 | CG7: 297130 | CH7: 220558 | CI7: =CH7-CG7 -> -76572 | CJ7: 76572 | CK7: 0
A9: Peak demand: 51.0 kW
A10: LTHP Sims done 5.18.26 (Marion)
C12: Added Life Cycle Cost | D12: Year 1 Added Elec Cost | E12: Annual %
A13: LT Heat Pumps, no PV, full cost | B13: No PV, Full cost | C13: 86028 | D13: 15379 | E13: 0
A14: LT Heat Pumps, no PV, free capital | B14: No PV, NPV | C14: -9846 | D14: 15379 | E14: 0
A15: LT Heat Pumps, net metering, full cost | B15: Net metering, Full cost | C15: -74069 | D15: 5594 | E15: 0.47
A16: LT Heat Pumps, net metering, free capital | B16: Net metering, NPV | C16: -112478 | D16: 5165 | E16: 0.49
A17: LT Heat Pumps, net billing, full cost | B17: Net billing, Full cost | C17: 33927 | D17: 10109 | E17: 0.32
A18: LT Heat Pumps, net billing, free capital | B18: Net billing, NPV | C18: -76572 | D18: 8136 | E18: 0.49
C20: Added Life Cycle Cost | D20: Year 1 Added Elec Cost | E20: Annual % | F20: Life Cycle Cost
B21: Propane: Fixed Controls | F21: 860764
A22: LT Heat Pumps, no PV, full cost | B22: No PV | C22: 86028 | D22: 15379 | E22: 0 | F22: 946792
A23: LT Heat Pumps, net metering, full cost | B23: Net metering | C23: -74069 | D23: 5594 | E23: 0.47 | F23: 786695
A24: LT Heat Pumps, net billing, full cost | B24: Net billing | C24: 33927 | D24: 10109 | E24: 0.32 | F24: 894691
C26: Added Life Cycle Cost | D26: Year 1 Added Elec Cost | E26: Annual % | F26: Life Cycle Cost
B27: Fixed Controls | F27: 297130
A28: LT Heat Pumps, no PV, full cost | B28: No PV | C28: -9846 | D28: 15379 | E28: 0 | F28: 287284
A29: LT Heat Pumps, net metering, full cost | B29: Net metering | C29: -112478 | D29: 5165 | E29: 0.49 | F29: 184652
A30: LT Heat Pumps, net billing, full cost | B30: Net billing | C30: -76572 | D30: 8136 | E30: 0.49 | F30: 220558

Sheet HT Heat Pumps
A1: Scenario | B1: Neither | C1: Net metering | D1: Net billing | E1: No PV | F1: CEC & EC PV | G1: Full cost (25 year) | H1: NPV savings (10 year) | I1: REopt Results: | J1: Select Technologies to Evaluate | K1: Air-Source Heat Pump configuration | L1: Evaluation name | M1: Site location (latitude, longitude) | N1: PV & wind space available | O1: Roofspace available (sq ft) | P1: Electricity rate | Q1: Compensation type | R1: Net metering system size limit (kW) | S1: Net billing compensation for all exports ($/kWh) | T1: Existing heating system fuel type | U1: Annual existing heating system fuel cost ($/gallon) | V1: Upload typical electric load profile | W1: Year of load profile | X1: Upload typical heating load profile | Y1: Space heating load percent of total heating load (%) | Z1: Year of load profile | AA1: Existing heating system efficiency (% HHV-basis) | AB1: Analysis period (years) | AC1: Host discount rate, nominal (%) | AD1: Electricity cost escalation rate, nominal (%/year) | AE1: Existing heating system fuel cost escalation rate, nominal (%/year) | AF1: Host effective tax rate (%) | AG1: Emissions | AH1: Size class | AI1: System capital cost ($/kW-DC) | AJ1: Array type | AK1: Array azimuth (deg) | AL1: Array tilt (deg) | AM1: Federal Incentive based on percentage of cost (%) | AN1: MACRS schedule | AO1: MACRS bonus depreciation | AP1: Energy capacity cost ($/kWh) | AQ1: Power capacity cost ($/kW) | AR1: Constant cost ($) | AS1: Minimum energy capacity (kWh) | AT1: Maximum energy capacity (kWh) | AU1: Energy capacity replacement cost ($/kWh) | AV1: Power capacity replacement cost ($/kWh) | AW1: Constant replacement cost ($) | AX1: Minimum power capacity (kW) | AY1: Maximum power capacity (kW) | AZ1: Federal Incentive based on percentage of cost (%) | BA1: MACRS schedule | BB1: MACRS bonus depreciation | BC1: Total installed cost ($/ton) | BD1: Upload COP Table | BE1: Heat pump capacity sizing factor | BF1: Resistive heating back-up temperature threshold (°F) | BG1: MACRS schedule | BH1: MACRS bonus depreciation | BI1: REopt Results: | BJ1: Optimized PV size (kW) | BK1: Optimized ASHP size (tonnes) | BL1: Potential Life Cycle Savings | BM1: Avg. Annual Grid Serving Load (kWh) | BN1: Avg. Annual Grid Charging Battery (kWh) | BO1: Avg. Annual Grid Total Electricity Consumed (kWh) | BP1: Avg. Annual PV Serving Load (kWh) | BQ1: Avg. Annual PV Charging Battery (kWh) | BR1: Avg. Annual PV Exported to Grid (kWh) | BS1: Avg. Annual PV Curtailment (kWh) | BT1: Avg. Annual PV Total Electricity Produced (kWh) | BU1: Avg. Annual Battery Serving Load (kWh) | BV1: BAU Average Annual Energy Supplied from Grid (kWh) | BW1: System Average Annual Energy Supplied from Grid (kWh) | BX1: Difference in Avg. Annual Energy Supplied from Grid | BY1: w/PV Annual Renewable Electricity (% of electricity consumed) | BZ1: BAU Total Year 1 Elec Cost - Pre-Tax | CA1: Total Year 1 Elec Cost - Pre-Tax | CB1: Difference Total Year 1 Elec Cost | CC1: BAU Total Full Period Elec Cost | CD1: Optimized Total Full Period Elec Cost | CE1: Difference in Full Period Utility Cost | CF1: BAUTotal Life Cycle Costs | CG1: Total Life Cycle Costs | CI1: Net Present Value | CJ1: Payback Period for PV /Battery (yrs)
A2: HT Heat Pumps, no PV, full cost | I2: HT Heat Pumps, no PV, full cost | REopt Web Tool | REopt Energy Integration & Optimization | NLR | J2: ASHP | K2: 2: Full replacement heating | L2: HT Heat Pumps, no PV, full cost | M2: 47.85212, -122.56923 | N2: Roofspace only | O2: 8000 | P2: PSE: 25 | Q2: N/A | R2: - | S2: - | T2: propane | U2: 2.01 | V2: https://drive.google.com/file/d/1Xl5WOtWsJzfbC-Y8nCxkp4Y4Mozirc_L/view?usp=drive_link | W2: 2024 | X2: https://drive.google.com/file/d/12MjGV739OVxdOUym7sn516wQM4dv51MR/view?usp=drive_link | Y2: 100 | Z2: 2024 | AA2: 83.07 | AB2: 25 | AC2: 2.5 | AD2: 6 | AE2: 7.8 | AF2: 0 | AG2: - | AH2: - | AI2: - | AJ2: - | AK2: - | AL2: - | AM2: - | AN2: - | AO2: - | AP2: - | AQ2: - | AR2: - | AS2: - | AT2: - | AU2: - | AV2: - | AW2: - | AX2: - | AY2: - | AZ2: - | BA2: - | BB2: - | BC2: 0 | BD2: https://drive.google.com/file/d/16UAUdtQOC8qioWbnM096MsZ4fLvZ1Viy/view?usp=drive_link | BE2: 1 | BF2: 30 | BG2: No MACRS | BH2: 0 | BI2: HT Heat Pumps, no PV, full cost | REopt Web Tool | REopt Energy Integration & Optimization | NLR | BJ2: 0 | BK2: 38 | BL2: -322823 | BM2: 166778 | BN2: 0 | BO2: 166778 | BP2: 0 | BQ2: 0 | BR2: 0 | BS2: 0 | BT2: 0 | BU2: 0 | BV2: 44197 | BW2: 166778 | BX2: 122581 | BY2: 0 | BZ2: 8394 | CA2: 29719 | CB2: 21326 | CC2: 334284 | CD2: 1183586 | CE2: 849302 | CF2: 860764 | CG2: 1183586 | CH2: =-1*CI2 -> 322822 | CI2: =CF2-CG2 -> -322822
A3: HT Heat Pumps, no PV, free capital | I3: HT Heat Pumps, no PV, free capital | REopt Web Tool | REopt Energy Integration & Optimization | NLR | J3: ASHP | K3: 2: Full replacement heating | L3: HT Heat Pumps, no PV, free capital | M3: 47.85212, -122.56923 | N3: Roofspace only | O3: 8000 | P3: PSE: 25 | Q3: N/A | R3: - | S3: - | T3: propane | U3: 2.01 | V3: https://drive.google.com/file/d/1Xl5WOtWsJzfbC-Y8nCxkp4Y4Mozirc_L/view?usp=drive_link | W3: 2024 | X3: https://drive.google.com/file/d/12MjGV739OVxdOUym7sn516wQM4dv51MR/view?usp=drive_link | Y3: 100 | Z3: 2024 | AA3: 83.07 | AB3: 10 | AC3: 2.5 | AD3: 6 | AE3: 7.8 | AF3: 0 | AG3: - | AH3: - | AI3: - | AJ3: - | AK3: - | AL3: - | AM3: - | AN3: - | AO3: - | AP3: - | AQ3: - | AR3: - | AS3: - | AT3: - | AU3: - | AV3: - | AW3: - | AX3: - | AY3: - | AZ3: - | BA3: - | BB3: - | BC3: 0 | BD3: https://drive.google.com/file/d/16UAUdtQOC8qioWbnM096MsZ4fLvZ1Viy/view?usp=drive_link | BE3: 1 | BF3: 30 | BG3: No MACRS | BH3: 0 | BI3: HT Heat Pumps, no PV, free capital | REopt Web Tool | REopt Energy Integration & Optimization | NLR | BJ3: 0 | BK3: 38 | BL3: -62004 | BM3: 166778 | BN3: 0 | BO3: 166778 | BP3: 0 | BQ3: 0 | BR3: 0 | BS3: 0 | BT3: 0 | BU3: 0 | BV3: 44197 | BW3: 166778 | BX3: 122581 | BY3: 0 | BZ3: 8394 | CA3: 29719 | CB3: =CA3-BZ3 -> 21325 | CC3: 101431 | CD3: 359134 | CE3: 257703 | CF3: 297130 | CG3: 359134 | CH3: =-1*CI3 -> 62004 | CI3: =CF3-CG3 -> -62004
A4: HT Heat Pumps, net metering, full cost | I4: HT Heat Pumps, net metering, Full cost | REopt Web Tool | REopt Energy Integration & Optimization | NLR | J4: ASHP, PV | K4: 2: Full replacement heating | L4: HT Heat Pumps, net metering, full cost | M4: 47.85212, -122.56923 | N4: Roofspace only | O4: 8000 | P4: PSE: 25 | Q4: Net metering | R4: 100 | S4: - | T4: propane | U4: 2.01 | V4: https://drive.google.com/file/d/1Xl5WOtWsJzfbC-Y8nCxkp4Y4Mozirc_L/view?usp=drive_link | W4: 2024 | X4: https://drive.google.com/file/d/12MjGV739OVxdOUym7sn516wQM4dv51MR/view?usp=drive_link | Y4: 100 | Z4: 2024 | AA4: 83.07 | AB4: 25 | AC4: 2.5 | AD4: 6 | AE4: 7.8 | AF4: 0 | AG4: - | AH4: Small Commercial | AI4: 2220 | AJ4: Rooftop, Fixed | AK4: 335.4 | AL4: 10.7 | AM4: 0 | AN4: No MACRS | AO4: 0 | AP4: - | AQ4: - | AR4: - | AS4: - | AT4: - | AU4: - | AV4: - | AW4: - | AX4: - | AY4: - | AZ4: - | BA4: - | BB4: - | BC4: 0 | BD4: https://drive.google.com/file/d/16UAUdtQOC8qioWbnM096MsZ4fLvZ1Viy/view?usp=drive_link | BE4: 1 | BF4: 30 | BG4: No MACRS | BH4: 0 | BI4: HT Heat Pumps, net metering, Full cost | REopt Web Tool | REopt Energy Integration & Optimization | NLR | BJ4: 80 | BK4: 38 | BL4: -165234 | BM4: 136956 | BN4: 0 | BO4: 136956 | BP4: 29822 | BQ4: 0 | BR4: 32016 | BS4: 0 | BT4: 61838 | BU4: 0 | BV4: 44197 | BW4: 136956 | BX4: =BW4-BV4 -> 92759 | BY4: 0.37 | BZ4: 8394 | CA4: 19997 | CB4: 11603 | CC4: 334284 | CD4: 796398 | CE4: 462113 | CF4: 860764 | CG4: 1025998 | CH4: =-1*CI4 -> 165234 | CI4: =CF4-CG4 -> -165234
A5: HT Heat Pumps, net metering, free capital | I5: HT Heat Pumps, net metering, free capital | REopt Web Tool | REopt Energy Integration & Optimization | NLR | J5: ASHP, PV | K5: 2: Full replacement heating | L5: HT Heat Pumps, net metering, free capital | M5: 47.85212, -122.56923 | N5: Roofspace only | O5: 8000 | P5: PSE: 25 | Q5: Net metering | R5: 100 | S5: - | T5: propane | U5: 2.01 | V5: https://drive.google.com/file/d/1Xl5WOtWsJzfbC-Y8nCxkp4Y4Mozirc_L/view?usp=drive_link | W5: 2024 | X5: https://drive.google.com/file/d/12MjGV739OVxdOUym7sn516wQM4dv51MR/view?usp=drive_link | Y5: 100 | Z5: 2024 | AA5: 83.07 | AB5: 10 | AC5: 2.5 | AD5: 6 | AE5: 7.8 | AF5: 0 | AG5: - | AH5: Small Commercial | AI5: 0 | AJ5: Rooftop, Fixed | AK5: 335.4 | AL5: 10.7 | AM5: 0 | AN5: No MACRS | AO5: 0 | AP5: - | AQ5: - | AR5: - | AS5: - | AT5: - | AU5: - | AV5: - | AW5: - | AX5: - | AY5: - | AZ5: - | BA5: - | BB5: - | BC5: 0 | BD5: https://drive.google.com/file/d/16UAUdtQOC8qioWbnM096MsZ4fLvZ1Viy/view?usp=drive_link | BE5: 1 | BF5: 30 | BG5: No MACRS | BH5: 0 | BI5: HT Heat Pumps, net metering, free capital | REopt Web Tool | REopt Energy Integration & Optimization | NLR | BJ5: 80 | BK5: 38 | BL5: 39866 | BM5: 136352 | BN5: 0 | BO5: 136352 | BP5: 30426 | BQ5: 0 | BR5: 34215 | BS5: 0 | BT5: 64641 | BU5: 0 | BV5: 44197 | BW5: 136352 | BX5: =BW5-BV5 -> 92155 | BY5: 0.39 | BZ5: 8394 | CA5: 19568 | CB5: =CA5-BZ5 -> 11174 | CC5: 101431 | CD5: 236464 | CE5: =CD5-CC5 -> 135033 | CF5: 297130 | CG5: 257264 | CH5: =-1*CI5 -> -39866 | CI5: =CF5-CG5 -> 39866
A6: HT Heat Pumps, net billing, full cost | I6: HT Heat Pumps, net billing, full cost | REopt Web Tool | REopt Energy Integration & Optimization | NLR | J6: ASHP, PV | K6: 2: Full replacement heating | L6: HT Heat Pumps, net billing, full cost | M6: 47.85212, -122.56923 | N6: Roofspace only | O6: 8000 | P6: PSE: 25 | Q6: Net billing | R6: - | S6: 0.06713 | T6: propane | U6: 2.01 | V6: https://drive.google.com/file/d/1Xl5WOtWsJzfbC-Y8nCxkp4Y4Mozirc_L/view?usp=drive_link | W6: 2024 | X6: https://drive.google.com/file/d/12MjGV739OVxdOUym7sn516wQM4dv51MR/view?usp=drive_link | Y6: 100 | Z6: 2024 | AA6: 83.07 | AB6: 25 | AC6: 2.5 | AD6: 6 | AE6: 7.8 | AF6: 0 | AG6: - | AH6: Small Commercial | AI6: 2220 | AJ6: Rooftop, Fixed | AK6: 335.4 | AL6: 10.7 | AM6: 0 | AN6: No MACRS | AO6: 0 | AP6: - | AQ6: - | AR6: - | AS6: - | AT6: - | AU6: - | AV6: - | AW6: - | AX6: - | AY6: - | AZ6: - | BA6: - | BB6: - | BC6: 0 | BD6: https://drive.google.com/file/d/16UAUdtQOC8qioWbnM096MsZ4fLvZ1Viy/view?usp=drive_link | BE6: 1 | BF6: 30 | BG6: No MACRS | BH6: 0 | BI6: HT Heat Pumps, net billing, full cost | REopt Web Tool | REopt Energy Integration & Optimization | NLR | BJ6: 66 | BK6: 38 | BL6: -268592 | BM6: 139510 | BN6: 0 | BO6: =BM6 -> 139510 | BP6: 27268 | BQ6: 0 | BR6: 23752 | BS6: 0 | BT6: 51020 | BU6: 0 | BV6: 44197 | BW6: 139510 | BX6: =BW6-BV6 -> 95313 | BY6: 0.31 | BZ6: 8394 | CA6: 23601 | CB6: =CA6-BZ6 -> 15207 | CC6: 334284 | CD6: 939924 | CE6: =CD6-CC6 -> 605640 | CF6: 860764 | CG6: 1129356 | CH6: =-1*CI6 -> 268592 | CI6: =CF6-CG6 -> -268592
A7: HT Heat Pumps, net billing, free capital | I7: HT Heat Pumps, net billing, free capital | REopt Web Tool | REopt Energy Integration & Optimization | NLR | J7: ASHP, PV | K7: 2: Full replacement heating | L7: HT Heat Pumps, net billing, free capital | M7: 47.85212, -122.56923 | N7: Roofspace only | O7: 8000 | P7: PSE: 25 | Q7: Net billing | R7: - | S7: 0.06713 | T7: propane | U7: 2.01 | V7: https://drive.google.com/file/d/1Xl5WOtWsJzfbC-Y8nCxkp4Y4Mozirc_L/view?usp=drive_link | W7: 2024 | X7: https://drive.google.com/file/d/12MjGV739OVxdOUym7sn516wQM4dv51MR/view?usp=drive_link | Y7: 100 | Z7: 2024 | AA7: 83.07 | AB7: 10 | AC7: 2.5 | AD7: 6 | AE7: 7.8 | AF7: 0 | AG7: - | AH7: Small Commercial | AI7: 0 | AJ7: Rooftop, Fixed | AK7: 335.4 | AL7: 10.7 | AM7: 0 | AN7: No MACRS | AO7: 0 | AP7: - | AQ7: - | AR7: - | AS7: - | AT7: - | AU7: - | AV7: - | AW7: - | AX7: - | AY7: - | AZ7: - | BA7: - | BB7: - | BC7: 0 | BD7: https://drive.google.com/file/d/16UAUdtQOC8qioWbnM096MsZ4fLvZ1Viy/view?usp=drive_link | BE7: 1 | BF7: 30 | BG7: No MACRS | BH7: 0 | BI7: HT Heat Pumps, net billing, free capital | REopt Web Tool | REopt Energy Integration & Optimization | NLR | BJ7: 80 | BK7: 38 | BL7: 6047 | BM7: 136352 | BN7: 0 | BO7: 136352 | BP7: 30426 | BQ7: 0 | BR7: 34215 | BS7: 0 | BT7: 64641 | BU7: 0 | BV7: 44197 | BW7: 136352 | BX7: =BW7-BV7 -> 92155 | BY7: 0.39 | BZ7: 8394 | CA7: 22366 | CB7: =CA7-BZ7 -> 13972 | CC7: 101431 | CD7: 270283 | CE7: =CD7-CC7 -> 168852 | CF7: 297130 | CG7: 291084 | CH7: =-1*CI7 -> -6046 | CI7: =CF7-CG7 -> 6046
A9: Peak demand: 66.9 kW

Sheet Electric Boiler
A1: Scenario | B1: Neither | C1: Net metering | D1: Net billing | E1: No PV | F1: CEC & EC PV | G1: Full cost (25 year) | H1: NPV savings (10 year) | I1: REopt Results: | J1: Select Technologies to Evaluate | K1: Air-Source Heat Pump configuration | L1: Evaluation name | M1: Site location (latitude, longitude) | N1: PV & wind space available | O1: Roofspace available (sq ft) | P1: Electricity rate | Q1: Compensation type | R1: Net metering system size limit (kW) | S1: Net billing compensation for all exports ($/kWh) | T1: Existing heating system fuel type | U1: Annual existing heating system fuel cost ($/gallon) | V1: Upload typical electric load profile | W1: Year of load profile | X1: Upload typical heating load profile | Y1: Space heating load percent of total heating load (%) | Z1: Year of load profile | AA1: Existing heating system efficiency (% HHV-basis) | AB1: Analysis period (years) | AC1: Host discount rate, nominal (%) | AD1: Electricity cost escalation rate, nominal (%/year) | AE1: Existing heating system fuel cost escalation rate, nominal (%/year) | AF1: Host effective tax rate (%) | AG1: Emissions | AH1: Size class | AI1: System capital cost ($/kW-DC) | AJ1: Array type | AK1: Array azimuth (deg) | AL1: Array tilt (deg) | AM1: Federal Incentive based on percentage of cost (%) | AN1: MACRS schedule | AO1: MACRS bonus depreciation | AP1: Energy capacity cost ($/kWh) | AQ1: Power capacity cost ($/kW) | AR1: Constant cost ($) | AS1: Minimum energy capacity (kWh) | AT1: Maximum energy capacity (kWh) | AU1: Energy capacity replacement cost ($/kWh) | AV1: Power capacity replacement cost ($/kWh) | AW1: Constant replacement cost ($) | AX1: Minimum power capacity (kW) | AY1: Maximum power capacity (kW) | AZ1: Federal Incentive based on percentage of cost (%) | BA1: MACRS schedule | BB1: MACRS bonus depreciation | BC1: Total installed cost ($/ton) | BD1: Upload COP Table | BE1: Heat pump capacity sizing factor | BF1: Resistive heating back-up temperature threshold (°F) | BG1: MACRS schedule | BH1: MACRS bonus depreciation | BI1: REopt Results: | BJ1: Optimized PV size (kW) | BK1: Optimized ASHP size (tonnes) | BL1: Optimized Battery Power and Capacity (kW/kWh) | BM1: Potential Life Cycle Savings | BN1: Avg. Annual Grid Serving Load (kWh) | BO1: Avg. Annual Grid Charging Battery (kWh) | BP1: Avg. Annual Grid Total Electricity Consumed (kWh) | BQ1: Avg. Annual PV Serving Load (kWh) | BR1: Avg. Annual PV Charging Battery (kWh) | BS1: Avg. Annual PV Exported to Grid (kWh) | BT1: Avg. Annual PV Curtailment (kWh) | BU1: Avg. Annual PV Total Electricity Produced (kWh) | BV1: Avg. Annual Battery Serving Load (kWh) | BW1: BAU Average Annual Energy Supplied from Grid (kWh) | BX1: New System Average Annual Energy Supplied from Grid (kWh) | BY1: Difference in Avg. Annual Energy Supplied from Grid | BZ1: Annual Renewable Electricity (% of electricity consumed) | CA1: Avoided CO2e Emissions throughout Analysis Period | CB1: BAU Total Year 1 Elec Cost - Pre-Tax | CC1: New Total Year 1 Elec Cost - Pre-Tax | CD1: Difference Total Year 1 Elec Cost | CE1: BAU Total Full Period Elec Cost | CF1: New Total Full Period Elec Cost | CG1: Difference in Full Period Utility Cost | CH1: BAU Total Life Cycle Costs | CI1: New Total Life Cycle Costs | CJ1: Difference in Total life cycle costs | CK1: New System Net Present Value | CL1: Payback Period for PV/ASHP (yrs)
A2: Electric Boiler, no PV, full cost | I2: Electric Boiler, no PV, full cost | REopt Web Tool | REopt Energy | J2: ASHP | K2: 2: Full replacement heating | L2: Electric Boiler, no PV, full cost | M2: 47.85212, -122.56923 | N2: Roofspace only | O2: 8000 | P2: PSE: 25 | Q2: N/A | R2: - | S2: - | T2: propane | U2: 2.01 | V2: https://drive.google.com/file/d/1Xl5WOtWsJzfbC-Y8nCxkp4Y4Mozirc_L/view?usp=drive_link | W2: 2024 | X2: https://drive.google.com/file/d/12MjGV739OVxdOUym7sn516wQM4dv51MR/view?usp=drive_link | Y2: 100 | Z2: 2024 | AA2: 83.07 | AB2: 25 | AC2: 2.5 | AD2: 6 | AE2: 7.8 | AF2: 0 | AG2: - | AH2: - | AI2: - | AJ2: - | AK2: - | AL2: - | AM2: - | AN2: - | AO2: - | AP2: - | AQ2: - | AR2: - | AS2: - | AT2: - | AU2: - | AV2: - | AW2: - | AX2: - | AY2: - | AZ2: - | BA2: - | BB2: - | BC2: 0 | BD2: https://drive.google.com/file/d/1ierMR5pp-9e4Oh1RndrdR-TIpi-DdJ91/view?usp=drive_link | BE2: 1 | BF2: 10 | BG2: No MACRS | BH2: 0 | BI2: Electric Boiler, no PV, full cost | REopt Web Tool | REopt Energy | BJ2: - | BK2: 26 | BL2: - | BM2: -913453 | BN2: - | BO2: - | BP2: - | BQ2: - | BR2: - | BS2: - | BT2: - | BU2: - | BV2: - | BW2: 44197 | BX2: 249593 | BY2: 205396 | BZ2: 0 | CA2: 1137 | CB2: 8394 | CC2: 44550 | CD2: 36156 | CE2: 334284 | CF2: 1774216 | CG2: 1439932 | CH2: 860764 | CI2: 1774216 | CJ2: 913453 | CK2: -913453 | CL2: 0
A3: Electric Boiler, no PV, free capital | I3: Electric Boiler, no PV, free capital | REopt Web Tool | REopt Energy | J3: ASHP | K3: 2: Full replacement heating | L3: Electric Boiler, no PV, free capital | M3: 47.85212, -122.56923 | N3: Roofspace only | O3: 8000 | P3: PSE: 25 | Q3: N/A | R3: - | S3: - | T3: propane | U3: 2.01 | V3: https://drive.google.com/file/d/1Xl5WOtWsJzfbC-Y8nCxkp4Y4Mozirc_L/view?usp=drive_link | W3: 2024 | X3: https://drive.google.com/file/d/12MjGV739OVxdOUym7sn516wQM4dv51MR/view?usp=drive_link | Y3: 100 | Z3: 2024 | AA3: 83.07 | AB3: 10 | AC3: 2.5 | AD3: 6 | AE3: 7.8 | AF3: 0 | AG3: - | AH3: - | AI3: - | AJ3: - | AK3: - | AL3: - | AM3: - | AN3: - | AO3: - | AP3: - | AQ3: - | AR3: - | AS3: - | AT3: - | AU3: - | AV3: - | AW3: - | AX3: - | AY3: - | AZ3: - | BA3: - | BB3: - | BC3: 0 | BD3: https://drive.google.com/file/d/1ierMR5pp-9e4Oh1RndrdR-TIpi-DdJ91/view?usp=drive_link | BE3: 1 | BF3: 10 | BG3: No MACRS | BH3: 0 | BI3: Electric Boiler, no PV, free capital | REopt Web Tool | REopt Energy | BJ3: - | BK3: 26 | BL3: - | BM3: -241218 | BN3: - | BO3: - | BP3: - | BQ3: - | BR3: - | BS3: - | BT3: - | BU3: - | BV3: - | BW3: 44197 | BX3: 249593 | BY3: 205396 | BZ3: 0 | CA3: 434 | CB3: 8394 | CC3: 44550 | CD3: 36156 | CE3: 101431 | CF3: 538348 | CG3: 436917 | CH3: 297130 | CI3: 538348 | CJ3: 241218 | CK3: -241218 | CL3: 0
A4: Electric Boiler, net metering, full cost | I4: Electric Boiler, net metering, full cost | REopt Web Tool | REopt Energy | J4: ASHP, PV | K4: 2: Full replacement heating | L4: Electric Boiler, net metering, full cost | M4: 47.85212, -122.56923 | N4: Roofspace only | O4: 8000 | P4: PSE: 25 | Q4: Net metering | R4: 100 | S4: - | T4: propane | U4: 2.01 | V4: https://drive.google.com/file/d/1Xl5WOtWsJzfbC-Y8nCxkp4Y4Mozirc_L/view?usp=drive_link | W4: 2024 | X4: https://drive.google.com/file/d/12MjGV739OVxdOUym7sn516wQM4dv51MR/view?usp=drive_link | Y4: 100 | Z4: 2024 | AA4: 83.07 | AB4: 25 | AC4: 2.5 | AD4: 6 | AE4: 7.8 | AF4: 0 | AG4: - | AH4: Small Commercial | AI4: 2220 | AJ4: Rooftop, Fixed | AK4: 335.4 | AL4: 10.7 | AM4: 0 | AN4: No MACRS | AO4: 0 | AP4: - | AQ4: - | AR4: - | AS4: - | AT4: - | AU4: - | AV4: - | AW4: - | AX4: - | AY4: - | AZ4: - | BA4: - | BB4: - | BC4: 0 | BD4: https://drive.google.com/file/d/1ierMR5pp-9e4Oh1RndrdR-TIpi-DdJ91/view?usp=drive_link | BE4: 1 | BF4: 10 | BG4: No MACRS | BH4: 0 | BI4: Electric Boiler, net metering, full cost | REopt Web Tool | REopt Energy | BJ4: 80 | BK4: 26 | BL4: - | BM4: -760007 | BN4: 216069 | BO4: - | BP4: 216069 | BQ4: 33524 | BR4: - | BS4: 28314 | BT4: 0 | BU4: 61838 | BV4: - | BW4: 44197 | BX4: 216069 | BY4: 171872 | BZ4: 0.25 | CA4: 1182 | CB4: 8394 | CC4: 34931 | CD4: 26538 | CE4: 334284 | CF4: 1391171 | CG4: 1056887 | CH4: 860764 | CI4: 1620771 | CJ4: 760007 | CK4: -760007 | CL4: 0
A5: Electric Boiler, net metering, free capital | I5: Electric Boiler, net metering, free capital | REopt Web Tool | REopt Energy Integration & Optimization | NLR | J5: ASHP, PV | K5: 2: Full replacement heating | L5: Electric Boiler, net metering, free capital | M5: 47.85212, -122.56923 | N5: Roofspace only | O5: 8000 | P5: PSE: 25 | Q5: Net metering | R5: 100 | S5: - | T5: propane | U5: 2.01 | V5: https://drive.google.com/file/d/1Xl5WOtWsJzfbC-Y8nCxkp4Y4Mozirc_L/view?usp=drive_link | W5: 2024 | X5: https://drive.google.com/file/d/12MjGV739OVxdOUym7sn516wQM4dv51MR/view?usp=drive_link | Y5: 100 | Z5: 2024 | AA5: 83.07 | AB5: 10 | AC5: 2.5 | AD5: 6 | AE5: 7.8 | AF5: 0 | AG5: - | AH5: Small Commercial | AI5: 0 | AJ5: Rooftop, Fixed | AK5: 335.4 | AL5: 10.7 | AM5: 0 | AN5: No MACRS | AO5: 0 | AP5: - | AQ5: - | AR5: - | AS5: - | AT5: - | AU5: - | AV5: - | AW5: - | AX5: - | AY5: - | AZ5: - | BA5: - | BB5: - | BC5: 0 | BD5: https://drive.google.com/file/d/1ierMR5pp-9e4Oh1RndrdR-TIpi-DdJ91/view?usp=drive_link | BE5: 1 | BF5: 10 | BG5: No MACRS | BH5: 0 | BI5: Electric Boiler, net metering, free capital | REopt Web Tool | REopt Energy Integration & Optimization | NLR | BJ5: 80 | BK5: 26 | BL5: - | BM5: -140615 | BN5: 215242 | BO5: - | BP5: 215242 | BQ5: 34351 | BR5: - | BS5: 30289 | BT5: 0 | BU5: 64641 | BV5: - | BW5: 44197 | BX5: 215242 | BY5: 171045 | BZ5: 0.26 | CA5: 470 | CB5: 8394 | CC5: 34503 | CD5: 26109 | CE5: 101431 | CF5: 416945 | CG5: 315514 | CH5: 297130 | CI5: 437745 | CJ5: 140615 | CK5: -140615 | CL5: 0
A6: Electric Boiler, net billing, full cost | I6: Electric Boiler, net billing, full cost | REopt Web Tool | REopt Energy Integration & Optimization | NLR | J6: ASHP, PV | K6: 2: Full replacement heating | L6: Electric Boiler, net billing, full cost | M6: 47.85212, -122.56923 | N6: Roofspace only | O6: 8000 | P6: PSE: 25 | Q6: Net billing | R6: - | S6: 0.06713 | T6: propane | U6: 2.01 | V6: https://drive.google.com/file/d/1Xl5WOtWsJzfbC-Y8nCxkp4Y4Mozirc_L/view?usp=drive_link | W6: 2024 | X6: https://drive.google.com/file/d/12MjGV739OVxdOUym7sn516wQM4dv51MR/view?usp=drive_link | Y6: 100 | Z6: 2024 | AA6: 83.07 | AB6: 25 | AC6: 2.5 | AD6: 6 | AE6: 7.8 | AF6: 0 | AG6: - | AH6: Small Commercial | AI6: 2220 | AJ6: Rooftop, Fixed | AK6: 335.4 | AL6: 10.7 | AM6: 0 | AN6: No MACRS | AO6: 0 | AP6: - | AQ6: - | AR6: - | AS6: - | AT6: - | AU6: - | AV6: - | AW6: - | AX6: - | AY6: - | AZ6: - | BA6: - | BB6: - | BC6: 0 | BD6: https://drive.google.com/file/d/1ierMR5pp-9e4Oh1RndrdR-TIpi-DdJ91/view?usp=drive_link | BE6: 1 | BF6: 10 | BG6: No MACRS | BH6: 0 | BI6: Electric Boiler, net billing, full cost | REopt Web Tool | REopt Energy Integration & Optimization | NLR | BJ6: 80 | BK6: 26 | BL6: - | BM6: -852242 | BN6: 216069 | BO6: - | BP6: 216069 | BQ6: 33524 | BR6: - | BS6: 28314 | BT6: 0 | BU6: 61838 | BV6: - | BW6: 44197 | BX6: 216069 | BY6: 171872 | BZ6: 0.25 | CA6: 1182 | CB6: 8394 | CC6: 37247 | CD6: 28854 | CE6: 334284 | CF6: 1483406 | CG6: 1149122 | CH6: 860764 | CI6: 1713006 | CJ6: 852242 | CK6: -852242 | CL6: 0
A7: Electric Boiler, net billing, free capital | I7: Electric Boiler, net billing, free capital | REopt Web Tool | REopt Energy Integration & Optimization | NLR | J7: ASHP, PV | K7: 2: Full replacement heating | L7: Electric Boiler, net billing, free capital | M7: 47.85212, -122.56923 | N7: Roofspace only | O7: 8000 | P7: PSE: 25 | Q7: Net billing | R7: - | S7: 0.06713 | T7: propane | U7: 2.01 | V7: https://drive.google.com/file/d/1Xl5WOtWsJzfbC-Y8nCxkp4Y4Mozirc_L/view?usp=drive_link | W7: 2024 | X7: https://drive.google.com/file/d/12MjGV739OVxdOUym7sn516wQM4dv51MR/view?usp=drive_link | Y7: 100 | Z7: 2024 | AA7: 83.07 | AB7: 10 | AC7: 2.5 | AD7: 6 | AE7: 7.8 | AF7: 0 | AG7: - | AH7: Small Commercial | AI7: 0 | AJ7: Rooftop, Fixed | AK7: 335.4 | AL7: 10.7 | AM7: 0 | AN7: No MACRS | AO7: 0 | AP7: - | AQ7: - | AR7: - | AS7: - | AT7: - | AU7: - | AV7: - | AW7: - | AX7: - | AY7: - | AZ7: - | BA7: - | BB7: - | BC7: 0 | BD7: https://drive.google.com/file/d/1ierMR5pp-9e4Oh1RndrdR-TIpi-DdJ91/view?usp=drive_link | BE7: 1 | BF7: 10 | BG7: No MACRS | BH7: 0 | BI7: Electric Boiler, net billing, free capital | REopt Web Tool | REopt Energy Integration & Optimization | NLR | BJ7: 80 | BK7: 26 | BL7: - | BM7: -170554 | BN7: 215242 | BO7: - | BP7: 215242 | BQ7: 34351 | BR7: - | BS7: 30289 | BT7: 0 | BU7: 64641 | BV7: - | BW7: 44197 | BX7: 215242 | BY7: 171045 | BZ7: 0.26 | CA7: 470 | CB7: 8394 | CC7: 36981 | CD7: 28587 | CE7: 101431 | CF7: 446884 | CG7: 345453 | CH7: 297130 | CI7: 467684 | CJ7: 170554 | CK7: -170554 | CL7: 0
A9: Peak demand: 100.5 kW
C11: Added Life Cycle Cost | D11: Year 1 Added Elec Cost | E11: Annual %
A12: Electric Boiler, no PV, full cost | B12: No PV, Full cost | C12: 913453 | D12: 36156 | E12: 0
A13: Electric Boiler, no PV, free capital | B13: No PV, NPV | C13: 241218 | D13: 36156 | E13: 0
A14: Electric Boiler, net metering, full cost | B14: Net metering, Full cost | C14: 760007 | D14: 26538 | E14: 0.25
A15: Electric Boiler, net billing, full cost | B15: Net billing, Full cost | C15: 852242 | D15: 28854 | E15: 0.25
A16: Electric Boiler, net billing, free capital | B16: Net billing, NPV | C16: 170554 | D16: 28587 | E16: 0.26
C18: Added Life Cycle Cost | D18: Year 1 Added Elec Cost | E18: Annual % | F18: Full Life Cycle Cost
A19: Electric Boiler, no PV, full cost | B19: No PV | C19: 913453 | D19: 36156 | E19: 0
A20: Electric Boiler, net metering, full cost | B20: Net metering | C20: 760007 | D20: 26538 | E20: 0.25
A21: Electric Boiler, net billing, full cost | B21: Net billing | C21: 852242 | D21: 28854 | E21: 0.25
C23: Added Life Cycle Cost | D23: Year 1 Added Elec Cost | E23: Annual %
A24: Electric Boiler, no PV, full cost | B24: No PV | C24: 241218 | D24: 36156 | E24: 0
A25: Electric Boiler, net metering, full cost | B25: Net metering | C25: 140615 | D25: 26109 | E25: 0.26
A26: Electric Boiler, net billing, full cost | B26: Net billing | C26: 170554 | D26: 28587 | E26: 0.26

Sheet LT Heat Pumps with Battery
A1: Scenario | B1: 1-hour Battery | C1: 2-hour Battery | D1: 4-hour Battery | E1: Net metering | F1: Net billing | G1: Full cost (25 year) | H1: NPV savings (10 year) | I1: REopt Results: | J1: Select Technologies to Evaluate | K1: Air-Source Heat Pump configuration | L1: Evaluation name | M1: Site location (latitude, longitude) | N1: PV & wind space available | O1: Roofspace available (sq ft) | P1: Electricity rate | Q1: Compensation type | R1: Net metering system size limit (kW) | S1: Net billing compensation for all exports ($/kWh) | T1: Existing heating system fuel type | U1: Annual existing heating system fuel cost ($/gallon) | V1: Upload typical electric load profile | W1: Year of load profile | X1: Upload typical heating load profile | Y1: Space heating load percent of total heating load (%) | Z1: Year of load profile | AA1: Existing heating system efficiency (% HHV-basis) | AB1: Analysis period (years) | AC1: Host discount rate, nominal (%) | AD1: Electricity cost escalation rate, nominal (%/year) | AE1: Existing heating system fuel cost escalation rate, nominal (%/year) | AF1: Host effective tax rate (%) | AG1: Emissions | AH1: Size class | AI1: System capital cost ($/kW-DC) | AJ1: Array type | AK1: Array azimuth (deg) | AL1: Array tilt (deg) | AM1: Federal Incentive based on percentage of cost (%) | AN1: MACRS schedule | AO1: MACRS bonus depreciation | AP1: Energy capacity cost ($/kWh) | AQ1: Power capacity cost ($/kW) | AR1: Constant cost ($) | AS1: Minimum energy capacity (kWh) | AT1: Maximum energy capacity (kWh) | AU1: Energy capacity replacement cost ($/kWh) | AV1: Power capacity replacement cost ($/kWh) | AW1: Constant replacement cost ($) | AX1: Minimum power capacity (kW) | AY1: Maximum power capacity (kW) | AZ1: Federal Incentive based on percentage of cost (%) | BA1: MACRS schedule | BB1: MACRS bonus depreciation | BC1: Total installed cost ($/ton) | BD1: Upload COP Table | BE1: Heat pump capacity sizing factor | BF1: Resistive heating back-up temperature threshold (°F) | BG1: MACRS schedule | BH1: MACRS bonus depreciation | BI1: REopt Results: | BJ1: Optimized PV size (kW) | BK1: Optimized ASHP size (tonnes) | BL1: Optimized Battery Power and Capacity (kW/kWh) | BM1: Potential Life Cycle Savings | BN1: Avg. Annual Grid Serving Load (kWh) | BO1: Avg. Annual Grid Charging Battery (kWh) | BP1: Avg. Annual Grid Total Electricity Consumed (kWh) | BQ1: Avg. Annual PV Serving Load (kWh) | BR1: Avg. Annual PV Charging Battery (kWh) | BS1: Avg. Annual PV Exported to Grid (kWh) | BT1: Avg. Annual PV Curtailment (kWh) | BU1: Avg. Annual PV Total Electricity Produced (kWh) | BV1: Avg. Annual Battery Serving Load (kWh) | BW1: BAU Average Annual Energy Supplied from Grid (kWh) | BX1: New System Average Annual Energy Supplied from Grid (kWh) | BY1: Difference in Avg. Annual Energy Supplied from Grid | BZ1: BAU Annual Renewable Electricity (% of electricity consumed) | CA1: Avoided CO2e Emissions throughout Analysis Period | CB1: BAU Total Year 1 Elec Cost - Pre-Tax | CC1: New Total Year 1 Elec Cost - Pre-Tax | CD1: Difference Total Year 1 Elec Cost | CE1: BAU Total Full Period Elec Cost | CF1: New Total Full Period Elec Cost | CG1: Difference in Full Period Utility Cost | CH1: BAU Total Life Cycle Costs | CI1: New Total Life Cycle Costs | CJ1: Difference in Total life cycle costs | CK1: New System Net Present Value | CL1: Payback Period for PV/ASHP (yrs)
A2: LT Heat Pumps, net metering, 1 hour battery, full cost | I2: LT Heat Pumps, net metering, 1 hour battery, full cost | REopt Web Tool | REopt Energy Integration & Optimization | NLR | J2: ASHP, Battery, PV | K2: 2: Full replacement heating | L2: LT Heat Pumps, net metering, 1 hour battery, full cost | M2: 47.85212, -122.56923 | N2: Roofspace only | O2: 8000 | P2: PSE: 25 | Q2: Net metering | R2: 100 | S2: - | T2: propane | U2: 2.01 | V2: https://drive.google.com/file/d/1Xl5WOtWsJzfbC-Y8nCxkp4Y4Mozirc_L/view?usp=drive_link | W2: 2024 | X2: https://drive.google.com/file/d/12MjGV739OVxdOUym7sn516wQM4dv51MR/view?usp=drive_link | Y2: 100 | Z2: 2024 | AA2: 83.07 | AB2: 25 | AC2: 2.5 | AD2: 6 | AE2: 7.8 | AF2: 0 | AG2: - | AH2: Small Commercial | AI2: 2220 | AJ2: Rooftop, Fixed | AK2: 335.4 | AL2: 10.7 | AM2: 0 | AN2: No MACRS | AO2: 0 | AP2: 495 | AQ2: 665 | AR2: 8066 | AS2: 10 | AT2: 10 | AU2: =0.7*AP2 -> 346.5 | AV2: =0.7*AQ2 -> 465.5 | AW2: =0.7*AR2 -> 5646.2 | AX2: 10 | AY2: 10 | AZ2: 0 | BA2: No MACRS | BB2: 0 | BC2: 0 | BD2: https://drive.google.com/file/d/1jrpu40DzxTFYY6LiD8LJLWmYTYBMVds2/view?usp=drive_link | BE2: 1 | BF2: 10 | BG2: No MACRS | BH2: 0 | BI2: LT Heat Pumps, net metering, 1 hour battery, full cost | REopt Web Tool | REopt Energy Integration & Optimization | NLR | BM2: 32224
A3: LT Heat Pumps, net metering, 1 hour battery, free capital | I3: LT Heat Pumps, net metering, 1 hour battery, free capital | REopt Web Tool | REopt Energy Integration & Optimization | NLR | J3: ASHP, Battery, PV | K3: 2: Full replacement heating | L3: LT Heat Pumps, net metering, 1 hour battery, free capital | M3: 47.85212, -122.56923 | N3: Roofspace only | O3: 8000 | P3: PSE: 25 | Q3: Net metering | R3: 100 | S3: - | T3: propane | U3: 2.01 | V3: https://drive.google.com/file/d/1Xl5WOtWsJzfbC-Y8nCxkp4Y4Mozirc_L/view?usp=drive_link | W3: 2024 | X3: https://drive.google.com/file/d/12MjGV739OVxdOUym7sn516wQM4dv51MR/view?usp=drive_link | Y3: 100 | Z3: 2024 | AA3: 83.07 | AB3: 10 | AC3: 2.5 | AD3: 6 | AE3: 7.8 | AF3: 0 | AG3: - | AH3: Small Commercial | AI3: 0 | AJ3: Rooftop, Fixed | AK3: 335.4 | AL3: 10.7 | AM3: 0 | AN3: No MACRS | AO3: 0 | AP3: 0 | AQ3: 0 | AR3: 0 | AS3: 10 | AT3: 10 | AU3: =0.7*AP3 -> 0 | AV3: =0.7*AQ3 -> 0 | AW3: =0.7*AR3 -> 0 | AX3: 10 | AY3: 10 | AZ3: 0 | BA3: No MACRS | BB3: 0 | BC3: 0 | BD3: https://drive.google.com/file/d/1jrpu40DzxTFYY6LiD8LJLWmYTYBMVds2/view?usp=drive_link | BE3: 1 | BF3: 10 | BG3: No MACRS | BH3: 0 | BI3: LT Heat Pumps, net metering, 1 hour battery, free capital | REopt Web Tool | REopt Energy Integration & Optimization | NLR | BM3: 112746
A4: LT Heat Pumps, net billing, 1 hour battery, full cost | I4: LT Heat Pumps, net billing, 1 hour battery, full cost | REopt Web Tool | REopt Energy Integration & Optimization | NLR | J4: ASHP, Battery, PV | K4: 2: Full replacement heating | L4: LT Heat Pumps, net billing, 1 hour battery, full cost | M4: 47.85212, -122.56923 | N4: Roofspace only | O4: 8000 | P4: PSE: 25 | Q4: Net billing | R4: - | S4: 0.06713 | T4: propane | U4: 2.01 | V4: https://drive.google.com/file/d/1Xl5WOtWsJzfbC-Y8nCxkp4Y4Mozirc_L/view?usp=drive_link | W4: 2024 | X4: https://drive.google.com/file/d/12MjGV739OVxdOUym7sn516wQM4dv51MR/view?usp=drive_link | Y4: 100 | Z4: 2024 | AA4: 83.07 | AB4: 25 | AC4: 2.5 | AD4: 6 | AE4: 7.8 | AF4: 0 | AG4: - | AH4: Small Commercial | AI4: 2220 | AJ4: Rooftop, Fixed | AK4: 335.4 | AL4: 10.7 | AM4: 0 | AN4: No MACRS | AO4: 0 | AP4: 495 | AQ4: 665 | AR4: 8066 | AS4: 10 | AT4: 10 | AU4: =0.7*AP4 -> 346.5 | AV4: =0.7*AQ4 -> 465.5 | AW4: =0.7*AR4 -> 5646.2 | AX4: 10 | AY4: 10 | AZ4: 0 | BA4: No MACRS | BB4: 0 | BC4: 0 | BD4: https://drive.google.com/file/d/1jrpu40DzxTFYY6LiD8LJLWmYTYBMVds2/view?usp=drive_link | BE4: 1 | BF4: 10 | BG4: No MACRS | BH4: 0 | BI4: LT Heat Pumps, net billing, 1 hour battery, full cost | REopt Web Tool | REopt Energy Integration & Optimization | NLR | BM4: -69986
A5: LT Heat Pumps, net billing, 1 hour battery, free capital | I5: LT Heat Pumps, net billing, 1 hour battery, free capital | REopt Web Tool | REopt Energy Integration & Optimization | NLR | J5: ASHP, Battery, PV | K5: 2: Full replacement heating | L5: LT Heat Pumps, net billing, 1 hour battery, free capital | M5: 47.85212, -122.56923 | N5: Roofspace only | O5: 8000 | P5: PSE: 25 | Q5: Net billing | R5: - | S5: 0.06713 | T5: propane | U5: 2.01 | V5: https://drive.google.com/file/d/1Xl5WOtWsJzfbC-Y8nCxkp4Y4Mozirc_L/view?usp=drive_link | W5: 2024 | X5: https://drive.google.com/file/d/12MjGV739OVxdOUym7sn516wQM4dv51MR/view?usp=drive_link | Y5: 100 | Z5: 2024 | AA5: 83.07 | AB5: 10 | AC5: 2.5 | AD5: 6 | AE5: 7.8 | AF5: 0 | AG5: - | AH5: Small Commercial | AI5: 0 | AJ5: Rooftop, Fixed | AK5: 335.4 | AL5: 10.7 | AM5: 0 | AN5: No MACRS | AO5: 0 | AP5: 0 | AQ5: 0 | AR5: 0 | AS5: 10 | AT5: 10 | AU5: =0.7*AP5 -> 0 | AV5: =0.7*AQ5 -> 0 | AW5: =0.7*AR5 -> 0 | AX5: 10 | AY5: 10 | AZ5: 0 | BA5: No MACRS | BB5: 0 | BC5: 0 | BD5: https://drive.google.com/file/d/1jrpu40DzxTFYY6LiD8LJLWmYTYBMVds2/view?usp=drive_link | BE5: 1 | BF5: 10 | BG5: No MACRS | BH5: 0 | BI5: LT Heat Pumps, net billing, 1 hour battery, free capital | REopt Web Tool | REopt Energy Integration & Optimization | NLR | BM5: 78825
A6: LT Heat Pumps, net metering, 2 hour battery, full cost | I6: LT Heat Pumps, net metering, 2 hour battery, full cost | REopt Web Tool | REopt Energy Integration & Optimization | NLR | J6: ASHP, Battery, PV | K6: 2: Full replacement heating | L6: LT Heat Pumps, net metering, 2 hour battery, full cost | M6: 47.85212, -122.56923 | N6: Roofspace only | O6: 8000 | P6: PSE: 25 | Q6: Net metering | R6: 100 | S6: - | T6: propane | U6: 2.01 | V6: https://drive.google.com/file/d/1Xl5WOtWsJzfbC-Y8nCxkp4Y4Mozirc_L/view?usp=drive_link | W6: 2024 | X6: https://drive.google.com/file/d/12MjGV739OVxdOUym7sn516wQM4dv51MR/view?usp=drive_link | Y6: 100 | Z6: 2024 | AA6: 83.07 | AB6: 25 | AC6: 2.5 | AD6: 6 | AE6: 7.8 | AF6: 0 | AG6: - | AH6: Small Commercial | AI6: 2220 | AJ6: Rooftop, Fixed | AK6: 335.4 | AL6: 10.7 | AM6: 0 | AN6: No MACRS | AO6: 0 | AP6: 495 | AQ6: 665 | AR6: 8066 | AS6: 20 | AT6: 20 | AU6: =0.7*AP6 -> 346.5 | AV6: =0.7*AQ6 -> 465.5 | AW6: =0.7*AR6 -> 5646.2 | AX6: 10 | AY6: 10 | AZ6: 0 | BA6: No MACRS | BB6: 0 | BC6: 0 | BD6: https://drive.google.com/file/d/1jrpu40DzxTFYY6LiD8LJLWmYTYBMVds2/view?usp=drive_link | BE6: 1 | BF6: 10 | BG6: No MACRS | BH6: 0 | BI6: LT Heat Pumps, net metering, 2 hour battery, full cost | REopt Web Tool | REopt Energy Integration & Optimization | NLR | BM6: 21612
A7: LT Heat Pumps, net metering, 2 hour battery, free capital | I7: LT Heat Pumps, net metering, 2 hour battery, free capital | REopt Web Tool | REopt Energy Integration & Optimization | NLR | J7: ASHP, Battery, PV | K7: 2: Full replacement heating | L7: LT Heat Pumps, net metering, 2 hour battery, free capital | M7: 47.85212, -122.56923 | N7: Roofspace only | O7: 8000 | P7: PSE: 25 | Q7: Net metering | R7: 100 | S7: - | T7: propane | U7: 2.01 | V7: https://drive.google.com/file/d/1Xl5WOtWsJzfbC-Y8nCxkp4Y4Mozirc_L/view?usp=drive_link | W7: 2024 | X7: https://drive.google.com/file/d/12MjGV739OVxdOUym7sn516wQM4dv51MR/view?usp=drive_link | Y7: 100 | Z7: 2024 | AA7: 83.07 | AB7: 10 | AC7: 2.5 | AD7: 6 | AE7: 7.8 | AF7: 0 | AG7: - | AH7: Small Commercial | AI7: 0 | AJ7: Rooftop, Fixed | AK7: 335.4 | AL7: 10.7 | AM7: 0 | AN7: No MACRS | AO7: 0 | AP7: 0 | AQ7: 0 | AR7: 0 | AS7: 20 | AT7: 20 | AU7: =0.7*AP7 -> 0 | AV7: =0.7*AQ7 -> 0 | AW7: =0.7*AR7 -> 0 | AX7: 10 | AY7: 10 | AZ7: 0 | BA7: No MACRS | BB7: 0 | BC7: 0 | BD7: https://drive.google.com/file/d/1jrpu40DzxTFYY6LiD8LJLWmYTYBMVds2/view?usp=drive_link | BE7: 1 | BF7: 10 | BG7: No MACRS | BH7: 0 | BI7: LT Heat Pumps, net metering, 2 hour battery, free capital | REopt Web Tool | REopt Energy Integration & Optimization | NLR | BM7: 112791
A8: LT Heat Pumps, net billing, 2 hour battery, full cost | I8: LT Heat Pumps, net billing, 2 hour battery, full cost | REopt Web Tool | REopt Energy Integration & Optimization | NLR | J8: ASHP, Battery, PV | K8: 2: Full replacement heating | L8: LT Heat Pumps, net billing, 2 hour battery, full cost | M8: 47.85212, -122.56923 | N8: Roofspace only | O8: 8000 | P8: PSE: 25 | Q8: Net billing | R8: - | S8: 0.06713 | T8: propane | U8: 2.01 | V8: https://drive.google.com/file/d/1Xl5WOtWsJzfbC-Y8nCxkp4Y4Mozirc_L/view?usp=drive_link | W8: 2024 | X8: https://drive.google.com/file/d/12MjGV739OVxdOUym7sn516wQM4dv51MR/view?usp=drive_link | Y8: 100 | Z8: 2024 | AA8: 83.07 | AB8: 25 | AC8: 2.5 | AD8: 6 | AE8: 7.8 | AF8: 0 | AG8: - | AH8: Small Commercial | AI8: 2220 | AJ8: Rooftop, Fixed | AK8: 335.4 | AL8: 10.7 | AM8: 0 | AN8: No MACRS | AO8: 0 | AP8: 495 | AQ8: 665 | AR8: 8066 | AS8: 20 | AT8: 20 | AU8: =0.7*AP8 -> 346.5 | AV8: =0.7*AQ8 -> 465.5 | AW8: =0.7*AR8 -> 5646.2 | AX8: 10 | AY8: 10 | AZ8: 0 | BA8: No MACRS | BB8: 0 | BC8: 0 | BD8: https://drive.google.com/file/d/1jrpu40DzxTFYY6LiD8LJLWmYTYBMVds2/view?usp=drive_link | BE8: 1 | BF8: 10 | BG8: No MACRS | BH8: 0 | BI8: LT Heat Pumps, net billing, 2 hour battery, full cost | REopt Web Tool | REopt Energy Integration & Optimization | NLR | BM8: -75364
A9: LT Heat Pumps, net billing, 2 hour battery, free capital | I9: LT Heat Pumps, net billing, 2 hour battery, free capital | REopt Web Tool | REopt Energy Integration & Optimization | NLR | J9: ASHP, Battery, PV | K9: 2: Full replacement heating | L9: LT Heat Pumps, net billing, 2 hour battery, free capital | M9: 47.85212, -122.56923 | N9: Roofspace only | O9: 8000 | P9: PSE: 25 | Q9: Net billing | R9: - | S9: 0.06713 | T9: propane | U9: 2.01 | V9: https://drive.google.com/file/d/1Xl5WOtWsJzfbC-Y8nCxkp4Y4Mozirc_L/view?usp=drive_link | W9: 2024 | X9: https://drive.google.com/file/d/12MjGV739OVxdOUym7sn516wQM4dv51MR/view?usp=drive_link | Y9: 100 | Z9: 2024 | AA9: 83.07 | AB9: 10 | AC9: 2.5 | AD9: 6 | AE9: 7.8 | AF9: 0 | AG9: - | AH9: Small Commercial | AI9: 0 | AJ9: Rooftop, Fixed | AK9: 335.4 | AL9: 10.7 | AM9: 0 | AN9: No MACRS | AO9: 0 | AP9: 0 | AQ9: 0 | AR9: 0 | AS9: 20 | AT9: 20 | AU9: =0.7*AP9 -> 0 | AV9: =0.7*AQ9 -> 0 | AW9: =0.7*AR9 -> 0 | AX9: 10 | AY9: 10 | AZ9: 0 | BA9: No MACRS | BB9: 0 | BC9: 0 | BD9: https://drive.google.com/file/d/1jrpu40DzxTFYY6LiD8LJLWmYTYBMVds2/view?usp=drive_link | BE9: 1 | BF9: 10 | BG9: No MACRS | BH9: 0 | BI9: LT Heat Pumps, net billing, 2 hour battery, free capital | REopt Web Tool | REopt Energy Integration & Optimization | NLR | BM9: 80636
